Workbook

Sheet JAN
A1: SOI BP's Completed TRACKER
A2: JANUARY 2026
A3: BC
A4: BP | B4: Assigned to | C4: Due | D4: Status | E4: Date Completed | F4: Score | H4: days Difference
A5: BC00 | B5: BEATRICE | C5: 46052.999 | D5: Done | E5: =IF(D5<>"",IF(E5="",NOW(),E5),"") -> 46051.11 | F5: =if(D5 = "", 0,IF(E5<C5,0.5,0)) -> 0.5 | H5: =if(D5 <> "", ABS(E5-C5), "0") -> 1.8894859
A6: BC01 | B6: BEATRICE | C6: 46052.999 | D6: Done | E6: =IF(D6<>"",IF(E6="",NOW(),E6),"") -> 46051.11 | F6: =if(D6 = "", 0,IF(E6<C6,0.5,0)) -> 0.5 | H6: =if(D6 <> "", ABS(E6-C6), "0") -> 1.8894495
A7: BC03 | B7: ARVIN | C7: 46024.999 | D7: Done | E7: =IF(D7<>"",IF(E7="",NOW(),E7),"") -> 46023.36 | F7: =if(D7 = "", 0,IF(E7<C7,0.5,0)) -> 0.5 | H7: =if(D7 <> "", ABS(E7-C7), "0") -> 1.6389588
A8: BC04 | B8: BRYLLE | C8: 46024.999 | D8: done | E8: =IF(D8<>"",IF(E8="",NOW(),E8),"") -> 46023.971 | F8: =if(D8 = "", 0,IF(E8<C8,0.5,0)) -> 0.5 | H8: =if(D8 <> "", ABS(E8-C8), "0") -> 1.0278874
A9: BC05 | B9: ROSHIEL | C9: 46027.999 | D9: done | E9: =IF(D9<>"",IF(E9="",NOW(),E9),"") -> 46027.103 | F9: =if(D9 = "", 0,IF(E9<C9,0.5,0)) -> 0.5 | H9: =if(D9 <> "", ABS(E9-C9), "0") -> 0.8960598
A10: BC07 | B10: ROSHIEL | C10: 46027.999 | D10: done | E10: =IF(D10<>"",IF(E10="",NOW(),E10),"") -> 46027.103 | F10: =if(D10 = "", 0,IF(E10<C10,0.5,0)) -> 0.5 | H10: =if(D10 <> "", ABS(E10-C10), "0") -> 0.8960452
A11: BC09 | B11: BEATRICE | C11: 46030.999 | D11: Done | E11: =IF(D11<>"",IF(E11="",NOW(),E11),"") -> 46028.988 | F11: =if(D11 = "", 0,IF(E11<C11,0.5,0)) -> 0.5 | H11: =if(D11 <> "", ABS(E11-C11), "0") -> 2.0110242
A12: BC10 | B12: BEATRICE | C12: 46030.999 | D12: Done | E12: =IF(D12<>"",IF(E12="",NOW(),E12),"") -> 46028.989 | F12: =if(D12 = "", 0,IF(E12<C12,0.5,0)) -> 0.5 | H12: =if(D12 <> "", ABS(E12-C12), "0") -> 2.0107146
A13: BC11 | B13: ROSHIEL | C13: 46031.999 | D13: done | E13: =IF(D13<>"",IF(E13="",NOW(),E13),"") -> 46031.411 | F13: =if(D13 = "", 0,IF(E13<C13,0.5,0)) -> 0.5 | H13: =if(D13 <> "", ABS(E13-C13), "0") -> 0.58781882
A14: BC13 | B14: GELO | C14: 46034.999 | D14: done | E14: =IF(D14<>"",IF(E14="",NOW(),E14),"") -> 46031.5 | F14: =if(D14 = "", 0,IF(E14<C14,0.5,0)) -> 0.5 | H14: =if(D14 <> "", ABS(E14-C14), "0") -> 3.4988272
A15: BC14 | B15: BRYLLE | C15: 46034.999 | D15: done | E15: =IF(D15<>"",IF(E15="",NOW(),E15),"") -> 46036.086 | F15: =if(D15 = "", 0,IF(E15<C15,0.5,0)) -> 0 | H15: =if(D15 <> "", ABS(E15-C15), "0") -> 1.0866272
A16: BC15 | B16: BRYLLE | C16: 46037.999 | D16: done | E16: =IF(D16<>"",IF(E16="",NOW(),E16),"") -> 46036.086 | F16: =if(D16 = "", 0,IF(E16<C16,0.5,0)) -> 0.5 | H16: =if(D16 <> "", ABS(E16-C16), "0") -> 1.9133492
... A25: BC28 | B25: SARAH | C25: 46048.999 | D25: done | E25: =IF(D25<>"",IF(E25="",NOW(),E25),"") -> 46048.201 | F25: =if(D25 = "", 0,IF(E25<C25,0.5,0)) -> 0.5 | H25: =if(D25 <> "", ABS(E25-C25), "0") -> 0.79843611
A26: AB
A27: BP | B27: Assigned to | C27: Due | D27: Status | E27: Date Completed | F27: Score | H27: days Difference
A28: AB00 | B28: BRYLLE | C28: 46052.999 | D28: done | E28: =IF(D28<>"",IF(E28="",NOW(),E28),"") -> 46051.373 | F28: =if(D28 = "", 0,IF(E28<C28,0.5,0)) -> 0.5 | H28: =if(D28 <> "", ABS(E28-C28), "0") -> 1.626267
A29: AB01 | B29: BRYLLE | C29: 46052.999 | D29: done | E29: =IF(D29<>"",IF(E29="",NOW(),E29),"") -> 46051.373 | F29: =if(D29 = "", 0,IF(E29<C29,0.5,0)) -> 0.5 | H29: =if(D29 <> "", ABS(E29-C29), "0") -> 1.6262448
A30: AB04 | B30: ROSHIEL | C30: 46024.999 | D30: done | E30: =IF(D30<>"",IF(E30="",NOW(),E30),"") -> 46023.164 | F30: =if(D30 = "", 0,IF(E30<C30,0.5,0)) -> 0.5 | H30: =if(D30 <> "", ABS(E30-C30), "0") -> 1.8357889
A31: AB07 | B31: BEATRICE | C31: 46027.999 | D31: Done | E31: =IF(D31<>"",IF(E31="",NOW(),E31),"") -> 46026.934 | F31: =if(D31 = "", 0,IF(E31<C31,0.5,0)) -> 0.5 | H31: =if(D31 <> "", ABS(E31-C31), "0") -> 1.0651087
A32: AB10 | B32: ROSHIEL | C32: 46030.999 | D32: done | E32: =IF(D32<>"",IF(E32="",NOW(),E32),"") -> 46029.149 | F32: =if(D32 = "", 0,IF(E32<C32,0.5,0)) -> 0.5 | H32: =if(D32 <> "", ABS(E32-C32), "0") -> 1.850188
A33: AB13 | B33: BRYLLE | C33: 46034.999 | D33: done | E33: =IF(D33<>"",IF(E33="",NOW(),E33),"") -> 46036.086 | F33: =if(D33 = "", 0,IF(E33<C33,0.5,0)) -> 0 | H33: =if(D33 <> "", ABS(E33-C33), "0") -> 1.0867474
A34: AB16 | B34: BEATRICE | C34: 46037.999 | D34: Done | E34: =IF(D34<>"",IF(E34="",NOW(),E34),"") -> 46036.126 | F34: =if(D34 = "", 0,IF(E34<C34,0.5,0)) -> 0.5 | H34: =if(D34 <> "", ABS(E34-C34), "0") -> 1.872809
A35: AB19 | B35: BRYLLE | C35: 46038.999 | D35: done | E35: =IF(D35<>"",IF(E35="",NOW(),E35),"") -> 46037.444 | F35: =if(D35 = "", 0,IF(E35<C35,0.5,0)) -> 0.5 | H35: =if(D35 <> "", ABS(E35-C35), "0") -> 1.5556272
A36: AB22 | B36: ART | C36: 46043.999 | D36: done | E36: =IF(D36<>"",IF(E36="",NOW(),E36),"") -> 46043.345 | F36: =if(D36 = "", 0,IF(E36<C36,0.5,0)) -> 0.5 | H36: =if(D36 <> "", ABS(E36-C36), "0") -> 0.65432417
A37: AB25 | B37: ART | C37: 46045.999 | D37: done | E37: =IF(D37<>"",IF(E37="",NOW(),E37),"") -> 46048.289 | F37: =if(D37 = "", 0,IF(E37<C37,0.5,0)) -> 0 | H37: =if(D37 <> "", ABS(E37-C37), "0") -> 2.2896434
A38: AB26 | B38: ART | C38: 46048.999 | D38: done | E38: =IF(D38<>"",IF(E38="",NOW(),E38),"") -> 46048.289 | F38: =if(D38 = "", 0,IF(E38<C38,0.5,0)) -> 0.5 | H38: =if(D38 <> "", ABS(E38-C38), "0") -> 0.71034587
A39: AB28 | B39: SARAH | C39: 46048.999 | E39: =IF(D39<>"",IF(E39="",NOW(),E39),"") | F39: =if(D39 = "", 0,IF(E39<C39,0.5,0)) -> 0 | H39: =if(D39 <> "", ABS(E39-C39), "0") -> 0
E1000: =IF(C1053<>"",IF(D1053="",NOW(),D1053),"")

Sheet FEB
A1: SOI BP's Completed TRACKER
A2: FEBRUARY 2026
A3: BC
A4: BP | B4: Assigned to | C4: Due | D4: Status | E4: Date Completed | F4: Score | H4: days Difference
A5: BC00 | B5: BEATRICE | C5: 46080.999 | D5: Done | E5: =IF(D5<>"",IF(E5="",NOW(),E5),"") -> 46082.955 | F5: =if(D5 = "", 0,IF(E5<C5,0.5,0)) -> 0 | H5: =if(D5 <> "", ABS(E5-C5), "0") -> 1.9557601
A6: BC01 | B6: BEATRICE | C6: 46080.999 | D6: Done | E6: =IF(D6<>"",IF(E6="",NOW(),E6),"") -> 46082.955 | F6: =if(D6 = "", 0,IF(E6<C6,0.5,0)) -> 0 | H6: =if(D6 <> "", ABS(E6-C6), "0") -> 1.9558045
A7: BC03 | B7: ARVIN | C7: 46055.999 | D7: Done | E7: =IF(D7<>"",IF(E7="",NOW(),E7),"") -> 46055.22 | F7: =if(D7 = "", 0,IF(E7<C7,0.5,0)) -> 0.5 | H7: =if(D7 <> "", ABS(E7-C7), "0") -> 0.77892097
A8: BC04 | B8: BRYLLE | C8: 46055.999 | D8: done | E8: =IF(D8<>"",IF(E8="",NOW(),E8),"") -> 46055.164 | F8: =if(D8 = "", 0,IF(E8<C8,0.5,0)) -> 0.5 | H8: =if(D8 <> "", ABS(E8-C8), "0") -> 0.83527176
A9: BC05 | B9: ROSHIEL | C9: 46058.999 | D9: done | E9: =IF(D9<>"",IF(E9="",NOW(),E9),"") -> 46058.321 | F9: =if(D9 = "", 0,IF(E9<C9,0.5,0)) -> 0.5 | H9: =if(D9 <> "", ABS(E9-C9), "0") -> 0.67820637
A10: BC07 | B10: ROSHIEL | C10: 46058.999 | D10: done | E10: =IF(D10<>"",IF(E10="",NOW(),E10),"") -> 46058.321 | F10: =if(D10 = "", 0,IF(E10<C10,0.5,0)) -> 0.5 | H10: =if(D10 <> "", ABS(E10-C10), "0") -> 0.67820186 | K10: 100
A11: BC09 | B11: BEATRICE | C11: 46059.999 | D11: Done | E11: =IF(D11<>"",IF(E11="",NOW(),E11),"") -> 46058.169 | F11: =if(D11 = "", 0,IF(E11<C11,0.5,0)) -> 0.5 | H11: =if(D11 <> "", ABS(E11-C11), "0") -> 1.8299248 | K11: 0
A12: BC10 | B12: BEATRICE | C12: 46059.999 | D12: Done | E12: =IF(D12<>"",IF(E12="",NOW(),E12),"") -> 46058.169 | F12: =if(D12 = "", 0,IF(E12<C12,0.5,0)) -> 0.5 | H12: =if(D12 <> "", ABS(E12-C12), "0") -> 1.8298252 | K12: 100
A13: BC11 | B13: ROSHIEL | C13: 46063.999 | D13: done | E13: =IF(D13<>"",IF(E13="",NOW(),E13),"") -> 46062.117 | F13: =if(D13 = "", 0,IF(E13<C13,0.5,0)) -> 0.5 | H13: =if(D13 <> "", ABS(E13-C13), "0") -> 1.88259 | K13: 0
A14: BC13 | B14: GELO | C14: 46065.999 | D14: done | E14: =IF(D14<>"",IF(E14="",NOW(),E14),"") -> 46064.48 | F14: =if(D14 = "", 0,IF(E14<C14,0.5,0)) -> 0.5 | H14: =if(D14 <> "", ABS(E14-C14), "0") -> 1.5196819
A15: BC14 | B15: BRYLLE | C15: 46065.999 | D15: done | E15: =IF(D15<>"",IF(E15="",NOW(),E15),"") -> 46065.115 | F15: =if(D15 = "", 0,IF(E15<C15,0.5,0)) -> 0.5 | H15: =if(D15 <> "", ABS(E15-C15), "0") -> 0.88382506
A16: BC15 | B16: BRYLLE | C16: 46066.999 | D16: done | E16: =IF(D16<>"",IF(E16="",NOW(),E16),"") -> 46065.116 | F16: =if(D16 = "", 0,IF(E16<C16,0.5,0)) -> 0.5 | H16: =if(D16 <> "", ABS(E16-C16), "0") -> 1.8836302
A17: BC17 | B17: GELO | C17: 46066.999 | D17: done | E17: =IF(D17<>"",IF(E17="",NOW(),E17),"") -> 46071.522 | F17: =if(D17 = "", 0,IF(E17<C17,0.5,0)) -> 0 | H17: =if(D17 <> "", ABS(E17-C17), "0") -> 4.5229832
A18: BC19 | B18: BEATRICE | C18: 46071.999 | D18: Done | E18: =IF(D18<>"",IF(E18="",NOW(),E18),"") -> 46070.93 | F18: =if(D18 = "", 0,IF(E18<C18,0.5,0)) -> 0.5 | H18: =if(D18 <> "", ABS(E18-C18), "0") -> 1.0692029
A19: BC20 | B19: SARAH | C19: 46071.999 | E19: =IF(D19<>"",IF(E19="",NOW(),E19),"") | F19: =if(D19 = "", 0,IF(E19<C19,0.5,0)) -> 0 | H19: =if(D19 <> "", ABS(E19-C19), "0") -> 0
A20: BC21 | B20: GELO | C20: 46073.999 | D20: done | E20: =IF(D20<>"",IF(E20="",NOW(),E20),"") -> 46071.522 | F20: =if(D20 = "", 0,IF(E20<C20,0.5,0)) -> 0.5 | H20: =if(D20 <> "", ABS(E20-C20), "0") -> 2.476897
A21: BC23 | B21: ARVIN | C21: 46073.999 | D21: Done | E21: =IF(D21<>"",IF(E21="",NOW(),E21),"") -> 46072.486 | F21: =if(D21 = "", 0,IF(E21<C21,0.5,0)) -> 0.5 | H21: =if(D21 <> "", ABS(E21-C21), "0") -> 1.5131209
A22: BC24 | B22: SARAH | C22: 46076.999 | D22: done | E22: =IF(D22<>"",IF(E22="",NOW(),E22),"") -> 46077.328 | F22: =if(D22 = "", 0,IF(E22<C22,0.5,0)) -> 0 | H22: =if(D22 <> "", ABS(E22-C22), "0") -> 0.3291326
A23: BC25 | B23: ARVIN | C23: 46076.999 | D23: Done | E23: =IF(D23<>"",IF(E23="",NOW(),E23),"") -> 46074.5 | F23: =if(D23 = "", 0,IF(E23<C23,0.5,0)) -> 0.5 | H23: =if(D23 <> "", ABS(E23-C23), "0") -> 2.4988975
A24: BC27 | B24: ROSHIEL | C24: 46079.999 | D24: done | E24: =IF(D24<>"",IF(E24="",NOW(),E24),"") -> 46078.238 | F24: =if(D24 = "", 0,IF(E24<C24,0.5,0)) -> 0.5 | H24: =if(D24 <> "", ABS(E24-C24), "0") -> 1.76171
A25: BC28 | B25: SARAH | C25: 46079.999 | D25: done | E25: =IF(D25<>"",IF(E25="",NOW(),E25),"") -> 46079.267 | F25: =if(D25 = "", 0,IF(E25<C25,0.5,0)) -> 0.5 | H25: =if(D25 <> "", ABS(E25-C25), "0") -> 0.73277311
A26: AB
A27: BP | B27: Assigned to | C27: Due | D27: Status | E27: Date Completed | F27: Score | H27: days Difference
A28: AB00 | B28: BRYLLE | C28: 46080.999 | D28: done | E28: =IF(D28<>"",IF(E28="",NOW(),E28),"") -> 46080.341 | F28: =if(D28 = "", 0,IF(E28<C28,0.5,0)) -> 0.5 | H28: =if(D28 <> "", ABS(E28-C28), "0") -> 0.65877582
A29: AB01 | B29: BRYLLE | C29: 46080.999 | D29: done | E29: =IF(D29<>"",IF(E29="",NOW(),E29),"") -> 46080.341 | F29: =if(D29 = "", 0,IF(E29<C29,0.5,0)) -> 0.5 | H29: =if(D29 <> "", ABS(E29-C29), "0") -> 0.65875505
A30: AB04 | B30: ROSHIEL | C30: 46055.999 | D30: done | E30: =IF(D30<>"",IF(E30="",NOW(),E30),"") -> 46055.125 | F30: =if(D30 = "", 0,IF(E30<C30,0.5,0)) -> 0.5 | H30: =if(D30 <> "", ABS(E30-C30), "0") -> 0.8746601
A31: AB07 | B31: BEATRICE | C31: 46058.999 | D31: Done | E31: =IF(D31<>"",IF(E31="",NOW(),E31),"") -> 46056.987 | F31: =if(D31 = "", 0,IF(E31<C31,0.5,0)) -> 0.5 | H31: =if(D31 <> "", ABS(E31-C31), "0") -> 2.0119394
A32: AB10 | B32: ROSHIEL | C32: 46059.999 | D32: done | E32: =IF(D32<>"",IF(E32="",NOW(),E32),"") -> 46058.321 | F32: =if(D32 = "", 0,IF(E32<C32,0.5,0)) -> 0.5 | H32: =if(D32 <> "", ABS(E32-C32), "0") -> 1.678102
A33: AB13 | B33: BRYLLE | C33: 46065.999 | D33: done | E33: =IF(D33<>"",IF(E33="",NOW(),E33),"") -> 46065.116 | F33: =if(D33 = "", 0,IF(E33<C33,0.5,0)) -> 0.5 | H33: =if(D33 <> "", ABS(E33-C33), "0") -> 0.8837867
A34: AB16 | B34: BEATRICE | C34: 46066.999 | D34: Done | E34: =IF(D34<>"",IF(E34="",NOW(),E34),"") -> 46064.97 | F34: =if(D34 = "", 0,IF(E34<C34,0.5,0)) -> 0.5 | H34: =if(D34 <> "", ABS(E34-C34), "0") -> 2.0289583
A35: AB19 | B35: BRYLLE | C35: 46071.999 | D35: done | E35: =IF(D35<>"",IF(E35="",NOW(),E35),"") -> 46077.018 | F35: =if(D35 = "", 0,IF(E35<C35,0.5,0)) -> 0 | H35: =if(D35 <> "", ABS(E35-C35), "0") -> 5.0184648
A36: AB22 | B36: ART | C36: 46073.999 | D36: done | E36: =IF(D36<>"",IF(E36="",NOW(),E36),"") -> 46073.438 | F36: =if(D36 = "", 0,IF(E36<C36,0.5,0)) -> 0.5 | H36: =if(D36 <> "", ABS(E36-C36), "0") -> 0.56146574
A37: AB25 | B37: ART | C37: 46076.999 | D37: done | E37: =IF(D37<>"",IF(E37="",NOW(),E37),"") -> 46077.232 | F37: =if(D37 = "", 0,IF(E37<C37,0.5,0)) -> 0 | H37: =if(D37 <> "", ABS(E37-C37), "0") -> 0.23263793
A38: AB26 | B38: ART | C38: 46079.999 | D38: Done | E38: =IF(D38<>"",IF(E38="",NOW(),E38),"") -> 46079.095 | F38: =if(D38 = "", 0,IF(E38<C38,0.5,0)) -> 0.5 | H38: =if(D38 <> "", ABS(E38-C38), "0") -> 0.90405958
A39: AB28 | B39: SARAH | C39: 46079.999 | E39: =IF(D39<>"",IF(E39="",NOW(),E39),"") | F39: =if(D39 = "", 0,IF(E39<C39,0.5,0)) -> 0 | H39: =if(D39 <> "", ABS(E39-C39), "0") -> 0

Sheet MAR
A1: SOI BP's Completed TRACKER
A2: MARCH 2026
A3: BC
A4: BP | B4: Assigned to | C4: Due | D4: Status | E4: Date Completed | F4: Score | H4: days Difference
A5: BC00 | B5: BEATRICE | C5: 46111.999 | D5: Done | E5: =IF(D5<>"",IF(E5="",NOW(),E5),"") -> 46110.872 | F5: =if(D5 = "", 0,IF(E5<C5,0.5,0)) -> 0.5 | H5: =if(D5 <> "", ABS(E5-C5), "0") -> 1.1275776
A6: BC01 | B6: BEATRICE | C6: 46111.999 | D6: Done | E6: =IF(D6<>"",IF(E6="",NOW(),E6),"") -> 46110.872 | F6: =if(D6 = "", 0,IF(E6<C6,0.5,0)) -> 0.5 | H6: =if(D6 <> "", ABS(E6-C6), "0") -> 1.1275359
A7: BC03 | B7: ARVIN | C7: 46083.999 | D7: Done | E7: =IF(D7<>"",IF(E7="",NOW(),E7),"") -> 46083.159 | F7: =if(D7 = "", 0,IF(E7<C7,0.5,0)) -> 0.5 | H7: =if(D7 <> "", ABS(E7-C7), "0") -> 0.84079998
A8: BC04 | B8: BRYLLE | C8: 46083.999 | D8: done | E8: =IF(D8<>"",IF(E8="",NOW(),E8),"") -> 46083.36 | F8: =if(D8 = "", 0,IF(E8<C8,0.5,0)) -> 0.5 | H8: =if(D8 <> "", ABS(E8-C8), "0") -> 0.63892887
A9: BC05 | B9: ROSHIEL | C9: 46086.999 | D9: done | E9: =IF(D9<>"",IF(E9="",NOW(),E9),"") -> 46085.313 | F9: =if(D9 = "", 0,IF(E9<C9,0.5,0)) -> 0.5 | H9: =if(D9 <> "", ABS(E9-C9), "0") -> 1.6860884
A10: BC07 | B10: ROSHIEL | C10: 46086.999 | D10: done | E10: =IF(D10<>"",IF(E10="",NOW(),E10),"") -> 46085.313 | F10: =if(D10 = "", 0,IF(E10<C10,0.5,0)) -> 0.5 | H10: =if(D10 <> "", ABS(E10-C10), "0") -> 1.6860763
A11: BC09 | B11: BEATRICE | C11: 46087.999 | D11: Done | E11: =IF(D11<>"",IF(E11="",NOW(),E11),"") -> 46086.195 | F11: =if(D11 = "", 0,IF(E11<C11,0.5,0)) -> 0.5 | H11: =if(D11 <> "", ABS(E11-C11), "0") -> 1.8038657
A12: BC10 | B12: BEATRICE | C12: 46087.999 | D12: Done | E12: =IF(D12<>"",IF(E12="",NOW(),E12),"") -> 46086.195 | F12: =if(D12 = "", 0,IF(E12<C12,0.5,0)) -> 0.5 | H12: =if(D12 <> "", ABS(E12-C12), "0") -> 1.8038202
A13: BC11 | B13: ROSHIEL | C13: 46091.999 | D13: done | E13: =IF(D13<>"",IF(E13="",NOW(),E13),"") -> 46092.397 | F13: =if(D13 = "", 0,IF(E13<C13,0.5,0)) -> 0 | H13: =if(D13 <> "", ABS(E13-C13), "0") -> 0.3977885
A14: BC13 | B14: GELO | C14: 46093.999 | D14: done | E14: =IF(D14<>"",IF(E14="",NOW(),E14),"") -> 46092.409 | F14: =if(D14 = "", 0,IF(E14<C14,0.5,0)) -> 0.5 | H14: =if(D14 <> "", ABS(E14-C14), "0") -> 1.5906685
A15: BC14 | B15: BRYLLE | C15: 46093.999 | D15: done | E15: =IF(D15<>"",IF(E15="",NOW(),E15),"") -> 46093.329 | F15: =if(D15 = "", 0,IF(E15<C15,0.5,0)) -> 0.5 | H15: =if(D15 <> "", ABS(E15-C15), "0") -> 0.67040242
A16: BC15 | B16: BRYLLE | C16: 46094.999 | D16: done | E16: =IF(D16<>"",IF(E16="",NOW(),E16),"") -> 46093.329 | F16: =if(D16 = "", 0,IF(E16<C16,0.5,0)) -> 0.5 | H16: =if(D16 <> "", ABS(E16-C16), "0") -> 1.6703709
... A25: BC28 | B25: SARAH | C25: 46107.999 | D25: done | E25: =IF(D25<>"",IF(E25="",NOW(),E25),"") -> 46107.37 | F25: =if(D25 = "", 0,IF(E25<C25,0.5,0)) -> 0.5 | H25: =if(D25 <> "", ABS(E25-C25), "0") -> 0.62939012
A26: AB
A27: BP | B27: Assigned to | C27: Due | D27: Status | E27: Date Completed | F27: Score | H27: days Difference
A28: AB00 | B28: BRYLLE | C28: 46111.999 | D28: done | E28: =IF(D28<>"",IF(E28="",NOW(),E28),"") -> 46111.091 | F28: =if(D28 = "", 0,IF(E28<C28,0.5,0)) -> 0.5 | H28: =if(D28 <> "", ABS(E28-C28), "0") -> 0.90787799
A29: AB01 | B29: BRYLLE | C29: 46111.999 | D29: done | E29: =IF(D29<>"",IF(E29="",NOW(),E29),"") -> 46111.091 | F29: =if(D29 = "", 0,IF(E29<C29,0.5,0)) -> 0.5 | H29: =if(D29 <> "", ABS(E29-C29), "0") -> 0.90785094
A30: AB04 | B30: ROSHIEL | C30: 46083.999 | D30: done | E30: =IF(D30<>"",IF(E30="",NOW(),E30),"") -> 46083.159 | F30: =if(D30 = "", 0,IF(E30<C30,0.5,0)) -> 0.5 | H30: =if(D30 <> "", ABS(E30-C30), "0") -> 0.84079998
A31: AB07 | B31: BEATRICE | C31: 46086.999 | D31: Done | E31: =IF(D31<>"",IF(E31="",NOW(),E31),"") -> 46085.039 | F31: =if(D31 = "", 0,IF(E31<C31,0.5,0)) -> 0.5 | H31: =if(D31 <> "", ABS(E31-C31), "0") -> 1.9606141 | J31: 100
A32: AB10 | B32: ROSHIEL | C32: 46087.999 | D32: done | E32: =IF(D32<>"",IF(E32="",NOW(),E32),"") -> 46086.179 | F32: =if(D32 = "", 0,IF(E32<C32,0.5,0)) -> 0.5 | H32: =if(D32 <> "", ABS(E32-C32), "0") -> 1.8204261 | J32: 100
A33: AB13 | B33: BRYLLE | C33: 46093.999 | D33: done | E33: =IF(D33<>"",IF(E33="",NOW(),E33),"") -> 46093.329 | F33: =if(D33 = "", 0,IF(E33<C33,0.5,0)) -> 0.5 | H33: =if(D33 <> "", ABS(E33-C33), "0") -> 0.67073362 | J33: 100
A34: AB16 | B34: BEATRICE | C34: 46094.999 | D34: Done | E34: =IF(D34<>"",IF(E34="",NOW(),E34),"") -> 46093.265 | F34: =if(D34 = "", 0,IF(E34<C34,0.5,0)) -> 0.5 | H34: =if(D34 <> "", ABS(E34-C34), "0") -> 1.7346759 | J34: 0
A35: AB19 | B35: BRYLLE | C35: 46099.999 | D35: done | E35: =IF(D35<>"",IF(E35="",NOW(),E35),"") -> 46098.343 | F35: =if(D35 = "", 0,IF(E35<C35,0.5,0)) -> 0.5 | H35: =if(D35 <> "", ABS(E35-C35), "0") -> 1.6564079
A36: AB22 | B36: ART | C36: 46101.999 | D36: done | E36: =IF(D36<>"",IF(E36="",NOW(),E36),"") -> 46101.405 | F36: =if(D36 = "", 0,IF(E36<C36,0.5,0)) -> 0.5 | H36: =if(D36 <> "", ABS(E36-C36), "0") -> 0.59388855
A37: AB25 | B37: ART | C37: 46104.999 | D37: done | E37: =IF(D37<>"",IF(E37="",NOW(),E37),"") -> 46104.382 | F37: =if(D37 = "", 0,IF(E37<C37,0.5,0)) -> 0.5 | H37: =if(D37 <> "", ABS(E37-C37), "0") -> 0.6176528
A38: AB26 | B38: ART | C38: 46107.999 | D38: done | E38: =IF(D38<>"",IF(E38="",NOW(),E38),"") -> 46108.096 | F38: =if(D38 = "", 0,IF(E38<C38,0.5,0)) -> 0 | H38: =if(D38 <> "", ABS(E38-C38), "0") -> 0.096734317
A39: AB28 | B39: SARAH | C39: 46107.999 | E39: =IF(D39<>"",IF(E39="",NOW(),E39),"") | F39: =if(D39 = "", 0,IF(E39<C39,0.5,0)) -> 0 | H39: =if(D39 <> "", ABS(E39-C39), "0") -> 0

Sheet APR
A1: SOI BP's Completed TRACKER
A2: APRIL 2026
A3: BC
A4: BP | B4: Assigned to | C4: Due | D4: Status | E4: Date Completed | F4: Score | H4: days Difference
A5: BC00 | B5: BEATRICE | C5: 46141.999 | D5: Done | E5: =IF(D5<>"",IF(E5="",NOW(),E5),"") -> 46139.987 | F5: =if(D5 = "", 0,IF(E5<C5,0.5,0)) -> 0.5 | H5: =if(D5 <> "", ABS(E5-C5), "0") -> 2.0123489
A6: BC01 | B6: BEATRICE | C6: 46141.999 | D6: Done | E6: =IF(D6<>"",IF(E6="",NOW(),E6),"") -> 46139.987 | F6: =if(D6 = "", 0,IF(E6<C6,0.5,0)) -> 0.5 | H6: =if(D6 <> "", ABS(E6-C6), "0") -> 2.0123083
A7: BC03 | B7: ARVIN | C7: 46114.999 | D7: Done | E7: =IF(D7<>"",IF(E7="",NOW(),E7),"") -> 46114.375 | F7: =if(D7 = "", 0,IF(E7<C7,0.5,0)) -> 0.5 | H7: =if(D7 <> "", ABS(E7-C7), "0") -> 0.6246519
A8: BC04 | B8: BRYLLE | C8: 46114.999 | D8: done | E8: =IF(D8<>"",IF(E8="",NOW(),E8),"") -> 46114.119 | F8: =if(D8 = "", 0,IF(E8<C8,0.5,0)) -> 0.5 | H8: =if(D8 <> "", ABS(E8-C8), "0") -> 0.88064446
A9: BC05 | B9: ROSHIEL | C9: 46114.999 | D9: done | E9: =IF(D9<>"",IF(E9="",NOW(),E9),"") -> 46113.36 | F9: =if(D9 = "", 0,IF(E9<C9,0.5,0)) -> 0.5 | H9: =if(D9 <> "", ABS(E9-C9), "0") -> 1.6393471
A10: BC07 | B10: ROSHIEL | C10: 46114.999 | D10: done | E10: =IF(D10<>"",IF(E10="",NOW(),E10),"") -> 46113.36 | F10: =if(D10 = "", 0,IF(E10<C10,0.5,0)) -> 0.5 | H10: =if(D10 <> "", ABS(E10-C10), "0") -> 1.6393354
A11: BC09 | B11: BEATRICE | C11: 46120.999 | D11: Done | E11: =IF(D11<>"",IF(E11="",NOW(),E11),"") -> 46119.949 | F11: =if(D11 = "", 0,IF(E11<C11,0.5,0)) -> 0.5 | H11: =if(D11 <> "", ABS(E11-C11), "0") -> 1.0506526
A12: BC10 | B12: BEATRICE | C12: 46120.999 | D12: Done | E12: =IF(D12<>"",IF(E12="",NOW(),E12),"") -> 46119.949 | F12: =if(D12 = "", 0,IF(E12<C12,0.5,0)) -> 0.5 | H12: =if(D12 <> "", ABS(E12-C12), "0") -> 1.0505945
A13: BC11 | B13: ROSHIEL | C13: 46122.999 | D13: DONE | E13: =IF(D13<>"",IF(E13="",NOW(),E13),"") -> 46121.546 | F13: =if(D13 = "", 0,IF(E13<C13,0.5,0)) -> 0.5 | H13: =if(D13 <> "", ABS(E13-C13), "0") -> 1.4530156
A14: BC13 | B14: GELO | C14: 46122.999 | D14: done | E14: =IF(D14<>"",IF(E14="",NOW(),E14),"") -> 46122.257 | F14: =if(D14 = "", 0,IF(E14<C14,0.5,0)) -> 0.5 | H14: =if(D14 <> "", ABS(E14-C14), "0") -> 0.74259925
A15: BC14 | B15: BRYLLE | C15: 46122.999 | D15: done | E15: =IF(D15<>"",IF(E15="",NOW(),E15),"") -> 46121.192 | F15: =if(D15 = "", 0,IF(E15<C15,0.5,0)) -> 0.5 | H15: =if(D15 <> "", ABS(E15-C15), "0") -> 1.8074719
A16: BC15 | B16: BRYLLE | C16: 46127.999 | D16: done | E16: =IF(D16<>"",IF(E16="",NOW(),E16),"") -> 46126.04 | F16: =if(D16 = "", 0,IF(E16<C16,0.5,0)) -> 0.5 | H16: =if(D16 <> "", ABS(E16-C16), "0") -> 1.9588679
... A25: BC28 | B25: SARAH | C25: 46136.999 | D25: done | E25: =IF(D25<>"",IF(E25="",NOW(),E25),"") -> 46135.413 | F25: =if(D25 = "", 0,IF(E25<C25,0.5,0)) -> 0.5 | H25: =if(D25 <> "", ABS(E25-C25), "0") -> 1.5859081
A26: AB
A27: BP | B27: Assigned to | C27: Due | D27: Status | E27: Date Completed | F27: Score | H27: days Difference
A28: AB00 | B28: BRYLLE | C28: 46141.999 | D28: done | E28: =IF(D28<>"",IF(E28="",NOW(),E28),"") -> 46141.074 | F28: =if(D28 = "", 0,IF(E28<C28,0.5,0)) -> 0.5 | H28: =if(D28 <> "", ABS(E28-C28), "0") -> 0.92566611
A29: AB01 | B29: BRYLLE | C29: 46141.999 | D29: done | E29: =IF(D29<>"",IF(E29="",NOW(),E29),"") -> 46141.074 | F29: =if(D29 = "", 0,IF(E29<C29,0.5,0)) -> 0.5 | H29: =if(D29 <> "", ABS(E29-C29), "0") -> 0.92563716
A30: AB04 | B30: ROSHIEL | C30: 46114.999 | D30: done | E30: =IF(D30<>"",IF(E30="",NOW(),E30),"") -> 46113.36 | F30: =if(D30 = "", 0,IF(E30<C30,0.5,0)) -> 0.5 | H30: =if(D30 <> "", ABS(E30-C30), "0") -> 1.6392423
A31: AB07 | B31: BEATRICE | C31: 46114.999 | D31: Done | E31: =IF(D31<>"",IF(E31="",NOW(),E31),"") -> 46117.933 | F31: =if(D31 = "", 0,IF(E31<C31,0.5,0)) -> 0 | H31: =if(D31 <> "", ABS(E31-C31), "0") -> 2.9336725
A32: AB10 | B32: ROSHIEL | C32: 46120.999 | D32: done | E32: =IF(D32<>"",IF(E32="",NOW(),E32),"") -> 46119.252 | F32: =if(D32 = "", 0,IF(E32<C32,0.5,0)) -> 0.5 | H32: =if(D32 <> "", ABS(E32-C32), "0") -> 1.7472082
A33: AB13 | B33: BRYLLE | C33: 46122.999 | D33: done | E33: =IF(D33<>"",IF(E33="",NOW(),E33),"") -> 46121.192 | F33: =if(D33 = "", 0,IF(E33<C33,0.5,0)) -> 0.5 | H33: =if(D33 <> "", ABS(E33-C33), "0") -> 1.8077272
A34: AB16 | B34: BEATRICE | C34: 46127.999 | D34: Done | E34: =IF(D34<>"",IF(E34="",NOW(),E34),"") -> 46126.238 | F34: =if(D34 = "", 0,IF(E34<C34,0.5,0)) -> 0.5 | H34: =if(D34 <> "", ABS(E34-C34), "0") -> 1.761303
A35: AB19 | B35: BRYLLE | C35: 46129.999 | D35: done | E35: =IF(D35<>"",IF(E35="",NOW(),E35),"") -> 46129.171 | F35: =if(D35 = "", 0,IF(E35<C35,0.5,0)) -> 0.5 | H35: =if(D35 <> "", ABS(E35-C35), "0") -> 0.82795302
A36: AB22 | B36: ART | C36: 46133.999 | D36: done | E36: =IF(D36<>"",IF(E36="",NOW(),E36),"") -> 46133.454 | F36: =if(D36 = "", 0,IF(E36<C36,0.5,0)) -> 0.5 | H36: =if(D36 <> "", ABS(E36-C36), "0") -> 0.54515378
A37: AB25 | B37: ART | C37: 46135.999 | D37: done | E37: =IF(D37<>"",IF(E37="",NOW(),E37),"") -> 46135.561 | F37: =if(D37 = "", 0,IF(E37<C37,0.5,0)) -> 0.5 | H37: =if(D37 <> "", ABS(E37-C37), "0") -> 0.43840341
A38: AB26 | B38: ART | C38: 46136.999 | D38: done | E38: =IF(D38<>"",IF(E38="",NOW(),E38),"") -> 46136.335 | F38: =if(D38 = "", 0,IF(E38<C38,0.5,0)) -> 0.5 | H38: =if(D38 <> "", ABS(E38-C38), "0") -> 0.6643942
A39: AB28 | B39: SARAH | C39: 46136.999 | E39: =IF(D39<>"",IF(E39="",NOW(),E39),"") | F39: =if(D39 = "", 0,IF(E39<C39,0.5,0)) -> 0 | H39: =if(D39 <> "", ABS(E39-C39), "0") -> 0

Sheet MAY
A1: SOI BP's Completed TRACKER
A2: MAY 2026
A3: BC
A4: BP | B4: Assigned to | C4: Due | D4: Status | E4: Date Completed | F4: Score | H4: days Difference
A5: BC00 | B5: BEATRICE | C5: 46171.999 | D5: Done | E5: =IF(D5<>"",IF(E5="",NOW(),E5),"") -> 46170.327 | F5: =if(D5 = "", 0,IF(E5<C5,0.5,0)) -> 0.5 | H5: =if(D5 <> "", ABS(E5-C5), "0") -> 1.6719021
A6: BC01 | B6: BEATRICE | C6: 46171.999 | D6: Done | E6: =IF(D6<>"",IF(E6="",NOW(),E6),"") -> 46170.327 | F6: =if(D6 = "", 0,IF(E6<C6,0.5,0)) -> 0.5 | H6: =if(D6 <> "", ABS(E6-C6), "0") -> 1.671875
A7: BC03 | B7: ARVIN | C7: 46143.999 | D7: Done | E7: =IF(D7<>"",IF(E7="",NOW(),E7),"") -> 46143.208 | F7: =if(D7 = "", 0,IF(E7<C7,0.5,0)) -> 0.5 | H7: =if(D7 <> "", ABS(E7-C7), "0") -> 0.7908291
A8: BC04 | B8: BRYLLE | C8: 46143.999 | D8: done | E8: =IF(D8<>"",IF(E8="",NOW(),E8),"") -> 46144.245 | F8: =if(D8 = "", 0,IF(E8<C8,0.5,0)) -> 0 | H8: =if(D8 <> "", ABS(E8-C8), "0") -> 0.24574257
A9: BC05 | B9: ROSHIEL | C9: 46147.999 | D9: done | E9: =IF(D9<>"",IF(E9="",NOW(),E9),"") -> 46146.012 | F9: =if(D9 = "", 0,IF(E9<C9,0.5,0)) -> 0.5 | H9: =if(D9 <> "", ABS(E9-C9), "0") -> 1.9870575
A10: BC07 | B10: ROSHIEL | C10: 46147.999 | D10: done | E10: =IF(D10<>"",IF(E10="",NOW(),E10),"") -> 46146.012 | F10: =if(D10 = "", 0,IF(E10<C10,0.5,0)) -> 0.5 | H10: =if(D10 <> "", ABS(E10-C10), "0") -> 1.9870531
A11: BC09 | B11: BEATRICE | C11: 46150.999 | D11: Done | E11: =IF(D11<>"",IF(E11="",NOW(),E11),"") -> 46149.309 | F11: =if(D11 = "", 0,IF(E11<C11,0.5,0)) -> 0.5 | H11: =if(D11 <> "", ABS(E11-C11), "0") -> 1.6902815
A12: BC10 | B12: BEATRICE | C12: 46150.999 | D12: Done | E12: =IF(D12<>"",IF(E12="",NOW(),E12),"") -> 46149.309 | F12: =if(D12 = "", 0,IF(E12<C12,0.5,0)) -> 0.5 | H12: =if(D12 <> "", ABS(E12-C12), "0") -> 1.6902076
A13: BC11 | B13: ROSHIEL | C13: 46150.999 | D13: done | E13: =IF(D13<>"",IF(E13="",NOW(),E13),"") -> 46149.168 | F13: =if(D13 = "", 0,IF(E13<C13,0.5,0)) -> 0.5 | H13: =if(D13 <> "", ABS(E13-C13), "0") -> 1.8313053
A14: BC13 | B14: GELO | C14: 46154.999 | D14: done | E14: =IF(D14<>"",IF(E14="",NOW(),E14),"") -> 46156.117 | F14: =if(D14 = "", 0,IF(E14<C14,0.5,0)) -> 0 | H14: =if(D14 <> "", ABS(E14-C14), "0") -> 1.1175662
A15: BC14 | B15: BRYLLE | C15: 46154.999 | D15: done | E15: =IF(D15<>"",IF(E15="",NOW(),E15),"") -> 46155.037 | F15: =if(D15 = "", 0,IF(E15<C15,0.5,0)) -> 0 | H15: =if(D15 <> "", ABS(E15-C15), "0") -> 0.038060637
A16: BC15 | B16: BRYLLE | C16: 46157.999 | D16: done | E16: =IF(D16<>"",IF(E16="",NOW(),E16),"") -> 46156.437 | F16: =if(D16 = "", 0,IF(E16<C16,0.5,0)) -> 0.5 | H16: =if(D16 <> "", ABS(E16-C16), "0") -> 1.5627542
A17: BC17 | B17: GELO | C17: 46157.999 | D17: done | E17: =IF(D17<>"",IF(E17="",NOW(),E17),"") -> 46156.117 | F17: =if(D17 = "", 0,IF(E17<C17,0.5,0)) -> 0.5 | H17: =if(D17 <> "", ABS(E17-C17), "0") -> 1.8823728 | K17: 1
A18: BC19 | B18: BEATRICE | C18: 46157.999 | D18: Done | E18: =IF(D18<>"",IF(E18="",NOW(),E18),"") -> 46157.302 | F18: =if(D18 = "", 0,IF(E18<C18,0.5,0)) -> 0.5 | H18: =if(D18 <> "", ABS(E18-C18), "0") -> 0.69721527 | K18: 1
A19: BC20 | B19: SARAH | C19: 46157.999 | D19: done | E19: =IF(D19<>"",IF(E19="",NOW(),E19),"") -> 46156.302 | F19: =if(D19 = "", 0,IF(E19<C19,0.5,0)) -> 0.5 | H19: =if(D19 <> "", ABS(E19-C19), "0") -> 1.6972961 | K19: 0
A20: BC21 | B20: GELO | C20: 46163.999 | D20: done | E20: =IF(D20<>"",IF(E20="",NOW(),E20),"") -> 46161.261 | F20: =if(D20 = "", 0,IF(E20<C20,0.5,0)) -> 0.5 | H20: =if(D20 <> "", ABS(E20-C20), "0") -> 2.7385426 | K20: 0
A21: BC23 | B21: ARVIN | C21: 46163.999 | D21: Done | E21: =IF(D21<>"",IF(E21="",NOW(),E21),"") -> 46162.333 | F21: =if(D21 = "", 0,IF(E21<C21,0.5,0)) -> 0.5 | H21: =if(D21 <> "", ABS(E21-C21), "0") -> 1.6664269
A22: BC24 | B22: SARAH | C22: 46164.999 | D22: done | E22: =IF(D22<>"",IF(E22="",NOW(),E22),"") -> 46164.306 | F22: =if(D22 = "", 0,IF(E22<C22,0.5,0)) -> 0.5 | H22: =if(D22 <> "", ABS(E22-C22), "0") -> 0.69297655
A23: BC25 | B23: ARVIN | C23: 46164.999 | D23: Done | E23: =IF(D23<>"",IF(E23="",NOW(),E23),"") -> 46164.322 | F23: =if(D23 = "", 0,IF(E23<C23,0.5,0)) -> 0.5 | H23: =if(D23 <> "", ABS(E23-C23), "0") -> 0.67709356
A24: BC27 | B24: ROSHIEL | C24: 46168.999 | D24: done | E24: =IF(D24<>"",IF(E24="",NOW(),E24),"") -> 46167.295 | F24: =if(D24 = "", 0,IF(E24<C24,0.5,0)) -> 0.5 | H24: =if(D24 <> "", ABS(E24-C24), "0") -> 1.7039546
A25: BC28 | B25: SARAH | C25: 46168.999 | D25: done | E25: =IF(D25<>"",IF(E25="",NOW(),E25),"") -> 46169.292 | F25: =if(D25 = "", 0,IF(E25<C25,0.5,0)) -> 0 | H25: =if(D25 <> "", ABS(E25-C25), "0") -> 0.29237135
A26: AB
A27: BP | B27: Assigned to | C27: Due | D27: Status | E27: Date Completed | F27: Score | H27: days Difference
A28: AB00 | B28: BRYLLE | C28: 46171.999 | D28: done | E28: =IF(D28<>"",IF(E28="",NOW(),E28),"") -> 46171.341 | F28: =if(D28 = "", 0,IF(E28<C28,0.5,0)) -> 0.5 | H28: =if(D28 <> "", ABS(E28-C28), "0") -> 0.65797917
A29: AB01 | B29: BRYLLE | C29: 46171.999 | D29: done | E29: =IF(D29<>"",IF(E29="",NOW(),E29),"") -> 46171.341 | F29: =if(D29 = "", 0,IF(E29<C29,0.5,0)) -> 0.5 | H29: =if(D29 <> "", ABS(E29-C29), "0") -> 0.6579499
A30: AB04 | B30: ROSHIEL | C30: 46143.999 | D30: done | E30: =IF(D30<>"",IF(E30="",NOW(),E30),"") -> 46142.408 | F30: =if(D30 = "", 0,IF(E30<C30,0.5,0)) -> 0.5 | H30: =if(D30 <> "", ABS(E30-C30), "0") -> 1.5914791
A31: AB07 | B31: BEATRICE | C31: 46147.999 | D31: Done | E31: =IF(D31<>"",IF(E31="",NOW(),E31),"") -> 46146.167 | F31: =if(D31 = "", 0,IF(E31<C31,0.5,0)) -> 0.5 | H31: =if(D31 <> "", ABS(E31-C31), "0") -> 1.8318885
A32: AB10 | B32: ROSHIEL | C32: 46150.999 | D32: Done | E32: =IF(D32<>"",IF(E32="",NOW(),E32),"") -> 46149.168 | F32: =if(D32 = "", 0,IF(E32<C32,0.5,0)) -> 0.5 | H32: =if(D32 <> "", ABS(E32-C32), "0") -> 1.8310606
A33: AB13 | B33: BRYLLE | C33: 46154.999 | D33: done | E33: =IF(D33<>"",IF(E33="",NOW(),E33),"") -> 46155.037 | F33: =if(D33 = "", 0,IF(E33<C33,0.5,0)) -> 0 | H33: =if(D33 <> "", ABS(E33-C33), "0") -> 0.037988079
A34: AB16 | B34: BEATRICE | C34: 46157.999 | D34: Done | E34: =IF(D34<>"",IF(E34="",NOW(),E34),"") -> 46157.302 | F34: =if(D34 = "", 0,IF(E34<C34,0.5,0)) -> 0.5 | H34: =if(D34 <> "", ABS(E34-C34), "0") -> 0.69715391
A35: AB19 | B35: BRYLLE | C35: 46157.999 | D35: done | E35: =IF(D35<>"",IF(E35="",NOW(),E35),"") -> 46156.437 | F35: =if(D35 = "", 0,IF(E35<C35,0.5,0)) -> 0.5 | H35: =if(D35 <> "", ABS(E35-C35), "0") -> 1.562633
A36: AB22 | B36: ART | C36: 46163.999 | D36: done | E36: =IF(D36<>"",IF(E36="",NOW(),E36),"") -> 46164.197 | F36: =if(D36 = "", 0,IF(E36<C36,0.5,0)) -> 0 | H36: =if(D36 <> "", ABS(E36-C36), "0") -> 0.19806459
A37: AB25 | B37: ART | C37: 46164.999 | D37: done | E37: =IF(D37<>"",IF(E37="",NOW(),E37),"") -> 46164.197 | F37: =if(D37 = "", 0,IF(E37<C37,0.5,0)) -> 0.5 | H37: =if(D37 <> "", ABS(E37-C37), "0") -> 0.80192825
A38: AB26 | B38: ART | C38: 46168.999 | D38: done | E38: =IF(D38<>"",IF(E38="",NOW(),E38),"") -> 46168.548 | F38: =if(D38 = "", 0,IF(E38<C38,0.5,0)) -> 0.5 | H38: =if(D38 <> "", ABS(E38-C38), "0") -> 0.45088698
A39: AB28 | B39: SARAH | C39: 46168.999 | E39: =IF(D39<>"",IF(E39="",NOW(),E39),"") | F39: =if(D39 = "", 0,IF(E39<C39,0.5,0)) -> 0 | H39: =if(D39 <> "", ABS(E39-C39), "0") -> 0

Sheet JUN
A1: SOI BP's Completed TRACKER
A2: 46174
A3: BC
A4: BP | B4: Assigned to | C4: Due | D4: Status | E4: Date Completed | F4: Score | H4: days Difference
A5: BC00 | B5: BEATRICE | C5: 46202.999 | D5: done | E5: =IF(D5<>"",IF(E5="",NOW(),E5),"") -> 46201.961 | F5: =if(D5 = "", 0,IF(E5<C5,0.5,0)) -> 0.5 | H5: =if(D5 <> "", ABS(E5-C5), "0") -> 1.0386917
A6: BC01 | B6: BEATRICE | C6: 46202.999 | D6: done | E6: =IF(D6<>"",IF(E6="",NOW(),E6),"") -> 46201.961 | F6: =if(D6 = "", 0,IF(E6<C6,0.5,0)) -> 0.5 | H6: =if(D6 <> "", ABS(E6-C6), "0") -> 1.0387581
A7: BC03 | B7: ARVIN | C7: 46175.999 | D7: Done | E7: =IF(D7<>"",IF(E7="",NOW(),E7),"") -> 46174.334 | F7: =if(D7 = "", 0,IF(E7<C7,0.5,0)) -> 0.5 | H7: =if(D7 <> "", ABS(E7-C7), "0") -> 1.6653608
A8: BC04 | B8: BRYLLE | C8: 46175.999 | D8: done | E8: =IF(D8<>"",IF(E8="",NOW(),E8),"") -> 46174.103 | F8: =if(D8 = "", 0,IF(E8<C8,0.5,0)) -> 0.5 | H8: =if(D8 <> "", ABS(E8-C8), "0") -> 1.8960696
A9: BC05 | B9: ROSHIEL | C9: 46178.999 | D9: done | E9: =IF(D9<>"",IF(E9="",NOW(),E9),"") -> 46178.396 | F9: =if(D9 = "", 0,IF(E9<C9,0.5,0)) -> 0.5 | H9: =if(D9 <> "", ABS(E9-C9), "0") -> 0.60298583
A10: BC07 | B10: ROSHIEL | C10: 46178.999 | D10: done | E10: =IF(D10<>"",IF(E10="",NOW(),E10),"") -> 46178.396 | F10: =if(D10 = "", 0,IF(E10<C10,0.5,0)) -> 0.5 | H10: =if(D10 <> "", ABS(E10-C10), "0") -> 0.60291557
A11: BC09 | B11: BEATRICE | C11: 46181.999 | D11: Done | E11: =IF(D11<>"",IF(E11="",NOW(),E11),"") -> 46181.311 | F11: =if(D11 = "", 0,IF(E11<C11,0.5,0)) -> 0.5 | H11: =if(D11 <> "", ABS(E11-C11), "0") -> 0.68820426 | K11: 1
A12: BC10 | B12: BEATRICE | C12: 46181.999 | D12: Done | E12: =IF(D12<>"",IF(E12="",NOW(),E12),"") -> 46181.311 | F12: =if(D12 = "", 0,IF(E12<C12,0.5,0)) -> 0.5 | H12: =if(D12 <> "", ABS(E12-C12), "0") -> 0.68814368 | K12: 1
A13: BC11 | B13: ROSHIEL | C13: 46183.999 | D13: done | E13: =IF(D13<>"",IF(E13="",NOW(),E13),"") -> 46182.298 | F13: =if(D13 = "", 0,IF(E13<C13,0.5,0)) -> 0.5 | H13: =if(D13 <> "", ABS(E13-C13), "0") -> 1.7014092 | K13: 1
A14: BC13 | B14: GELO | C14: 46185.999 | D14: done | E14: 46184.121 | F14: =if(D14 = "", 0,IF(E14<C14,0.5,0)) -> 0.5 | H14: =if(D14 <> "", ABS(E14-C14), "0") -> 1.8786921 | K14: 0
A15: BC14 | B15: BRYLLE | C15: 46185.999 | D15: done | E15: =IF(D15<>"",IF(E15="",NOW(),E15),"") -> 46184.093 | F15: =if(D15 = "", 0,IF(E15<C15,0.5,0)) -> 0.5 | H15: =if(D15 <> "", ABS(E15-C15), "0") -> 1.9059572
A16: BC15 | B16: BRYLLE | C16: 46188.999 | D16: done | E16: =IF(D16<>"",IF(E16="",NOW(),E16),"") -> 46189.18 | F16: =if(D16 = "", 0,IF(E16<C16,0.5,0)) -> 0 | H16: =if(D16 <> "", ABS(E16-C16), "0") -> 0.18079882
A17: BC17 | B17: GELO | C17: 46188.999 | D17: done | E17: =IF(D17<>"",IF(E17="",NOW(),E17),"") -> 46188.46 | F17: =if(D17 = "", 0,IF(E17<C17,0.5,0)) -> 0.5 | H17: =if(D17 <> "", ABS(E17-C17), "0") -> 0.53890676
A18: BC19 | B18: BEATRICE | C18: 46191.999 | D18: Done | E18: =IF(D18<>"",IF(E18="",NOW(),E18),"") -> 46192.13 | F18: =if(D18 = "", 0,IF(E18<C18,0.5,0)) -> 0 | H18: =if(D18 <> "", ABS(E18-C18), "0") -> 0.13101786
A19: BC20 | B19: SARAH | C19: 46191.999 | D19: done | E19: =IF(D19<>"",IF(E19="",NOW(),E19),"") -> 46191.365 | F19: =if(D19 = "", 0,IF(E19<C19,0.5,0)) -> 0.5 | H19: =if(D19 <> "", ABS(E19-C19), "0") -> 0.63445347
A20: BC21 | B20: GELO | C20: 46192.999 | D20: done | E20: =IF(D20<>"",IF(E20="",NOW(),E20),"") -> 46192.103 | F20: =if(D20 = "", 0,IF(E20<C20,0.5,0)) -> 0.5 | H20: =if(D20 <> "", ABS(E20-C20), "0") -> 0.89656403
A21: BC23 | B21: ARVIN | C21: 46192.999 | D21: Done | E21: =IF(D21<>"",IF(E21="",NOW(),E21),"") -> 46191.413 | F21: =if(D21 = "", 0,IF(E21<C21,0.5,0)) -> 0.5 | H21: =if(D21 <> "", ABS(E21-C21), "0") -> 1.5860092
A22: BC24 | B22: SARAH | C22: 46196.999 | D22: done | E22: =IF(D22<>"",IF(E22="",NOW(),E22),"") -> 46196.366 | F22: =if(D22 = "", 0,IF(E22<C22,0.5,0)) -> 0.5 | H22: =if(D22 <> "", ABS(E22-C22), "0") -> 0.63350644
A23: BC25 | B23: ARVIN | C23: 46196.999 | D23: Done | E23: =IF(D23<>"",IF(E23="",NOW(),E23),"") -> 46195.563 | F23: =if(D23 = "", 0,IF(E23<C23,0.5,0)) -> 0.5 | H23: =if(D23 <> "", ABS(E23-C23), "0") -> 1.4365992
A24: BC27 | B24: ROSHIEL | C24: 46199.999 | D24: done | E24: =IF(D24<>"",IF(E24="",NOW(),E24),"") -> 46198.447 | F24: =if(D24 = "", 0,IF(E24<C24,0.5,0)) -> 0.5 | H24: =if(D24 <> "", ABS(E24-C24), "0") -> 1.552451
A25: BC28 | B25: SARAH | C25: 46199.999 | D25: done | E25: =IF(D25<>"",IF(E25="",NOW(),E25),"") -> 46199.396 | F25: =if(D25 = "", 0,IF(E25<C25,0.5,0)) -> 0.5 | H25: =if(D25 <> "", ABS(E25-C25), "0") -> 0.6033731
A26: AB
A27: BP | B27: Assigned to | C27: Due | D27: Status | E27: Date Completed | F27: Score | H27: days Difference
A28: AB00 | B28: BRYLLE | C28: 46202.999 | D28: done | E28: =IF(D28<>"",IF(E28="",NOW(),E28),"") -> 46202.019 | F28: =if(D28 = "", 0,IF(E28<C28,0.5,0)) -> 0.5 | H28: =if(D28 <> "", ABS(E28-C28), "0") -> 0.98051102
A29: AB01 | B29: BRYLLE | C29: 46202.999 | D29: done | E29: =IF(D29<>"",IF(E29="",NOW(),E29),"") -> 46202.019 | F29: =if(D29 = "", 0,IF(E29<C29,0.5,0)) -> 0.5 | H29: =if(D29 <> "", ABS(E29-C29), "0") -> 0.98047905
A30: AB04 | B30: ROSHIEL | C30: 46175.999 | D30: done | E30: =IF(D30<>"",IF(E30="",NOW(),E30),"") -> 46174.291 | F30: =if(D30 = "", 0,IF(E30<C30,0.5,0)) -> 0.5 | H30: =if(D30 <> "", ABS(E30-C30), "0") -> 1.7085535
A31: AB07 | B31: BEATRICE | C31: 46178.999 | D31: Done | E31: =IF(D31<>"",IF(E31="",NOW(),E31),"") -> 46177.234 | F31: =if(D31 = "", 0,IF(E31<C31,0.5,0)) -> 0.5 | H31: =if(D31 <> "", ABS(E31-C31), "0") -> 1.7652849
A32: AB10 | B32: ROSHIEL | C32: 46181.999 | D32: done | E32: =IF(D32<>"",IF(E32="",NOW(),E32),"") -> 46181.196 | F32: =if(D32 = "", 0,IF(E32<C32,0.5,0)) -> 0.5 | H32: =if(D32 <> "", ABS(E32-C32), "0") -> 0.80379541
A33: AB13 | B33: BRYLLE | C33: 46185.999 | D33: done | E33: =IF(D33<>"",IF(E33="",NOW(),E33),"") -> 46184.093 | F33: =if(D33 = "", 0,IF(E33<C33,0.5,0)) -> 0.5 | H33: =if(D33 <> "", ABS(E33-C33), "0") -> 1.90601
A34: AB16 | B34: BEATRICE | C34: 46188.999 | D34: Done | E34: =IF(D34<>"",IF(E34="",NOW(),E34),"") -> 46188.193 | F34: =if(D34 = "", 0,IF(E34<C34,0.5,0)) -> 0.5 | H34: =if(D34 <> "", ABS(E34-C34), "0") -> 0.80640797
A35: AB19 | B35: BRYLLE | C35: 46191.999 | D35: done | E35: =IF(D35<>"",IF(E35="",NOW(),E35),"") -> 46192.095 | F35: =if(D35 = "", 0,IF(E35<C35,0.5,0)) -> 0 | H35: =if(D35 <> "", ABS(E35-C35), "0") -> 0.095780683
A36: AB22 | B36: ART | C36: 46192.999 | D36: done | E36: =IF(D36<>"",IF(E36="",NOW(),E36),"") -> 46195.311 | F36: =if(D36 = "", 0,IF(E36<C36,0.5,0)) -> 0 | H36: =if(D36 <> "", ABS(E36-C36), "0") -> 2.3118758
A37: AB25 | B37: ART | C37: 46196.999 | D37: done | E37: =IF(D37<>"",IF(E37="",NOW(),E37),"") -> 46196.164 | F37: =if(D37 = "", 0,IF(E37<C37,0.5,0)) -> 0.5 | H37: =if(D37 <> "", ABS(E37-C37), "0") -> 0.83522961
A38: AB26 | B38: ART | C38: 46199.999 | D38: done | E38: =IF(D38<>"",IF(E38="",NOW(),E38),"") -> 46199.208 | F38: =if(D38 = "", 0,IF(E38<C38,0.5,0)) -> 0.5 | H38: =if(D38 <> "", ABS(E38-C38), "0") -> 0.79158829
A39: AB28 | B39: SARAH | C39: 46199.999 | E39: =IF(D39<>"",IF(E39="",NOW(),E39),"") | F39: =if(D39 = "", 0,IF(E39<C39,0.5,0)) -> 0 | H39: =if(D39 <> "", ABS(E39-C39), "0") -> 0

Sheet JUL
A1: SOI BP's Completed TRACKER
A2: JULY 2026
A3: BC
A4: BP | B4: Assigned to | C4: Due | D4: Status | E4: Date Completed | F4: Score | H4: days Difference
A5: BC00 | B5: BEATRICE | C5: 46233.999 | D5: Done | E5: =IF(D5<>"",IF(E5="",NOW(),E5),"") -> 46233.261 | F5: =if(D5 = "", 0,IF(E5<C5,0.5,0)) -> 0.5 | H5: =if(D5 <> "", ABS(E5-C5), "0") -> 0.73795612
A6: BC01 | B6: BEATRICE | C6: 46233.999 | D6: Done | E6: =IF(D6<>"",IF(E6="",NOW(),E6),"") -> 46233.261 | F6: =if(D6 = "", 0,IF(E6<C6,0.5,0)) -> 0.5 | H6: =if(D6 <> "", ABS(E6-C6), "0") -> 0.73788321
A7: BC03 | B7: ARVIN | C7: 46205.999 | D7: Done | E7: =IF(D7<>"",IF(E7="",NOW(),E7),"") -> 46205.285 | F7: =if(D7 = "", 0,IF(E7<C7,0.5,0)) -> 0.5 | H7: =if(D7 <> "", ABS(E7-C7), "0") -> 0.71422093
A8: BC04 | B8: BRYLLE | C8: 46205.999 | D8: done | E8: =IF(D8<>"",IF(E8="",NOW(),E8),"") -> 46205.02 | F8: =if(D8 = "", 0,IF(E8<C8,0.5,0)) -> 0.5 | H8: =if(D8 <> "", ABS(E8-C8), "0") -> 0.97890326
A9: BC05 | B9: ROSHIEL | C9: 46206.999 | D9: done | E9: =IF(D9<>"",IF(E9="",NOW(),E9),"") -> 46204.328 | F9: =if(D9 = "", 0,IF(E9<C9,0.5,0)) -> 0.5 | H9: =if(D9 <> "", ABS(E9-C9), "0") -> 2.6712886 | J9: 0
A10: BC07 | B10: ROSHIEL | C10: 46206.999 | D10: done | E10: =IF(D10<>"",IF(E10="",NOW(),E10),"") -> 46204.328 | F10: =if(D10 = "", 0,IF(E10<C10,0.5,0)) -> 0.5 | H10: =if(D10 <> "", ABS(E10-C10), "0") -> 2.6712787 | J10: 100
A11: BC09 | B11: BEATRICE | C11: 46211.999 | D11: Done | E11: =IF(D11<>"",IF(E11="",NOW(),E11),"") -> 46210.317 | F11: =if(D11 = "", 0,IF(E11<C11,0.5,0)) -> 0.5 | H11: =if(D11 <> "", ABS(E11-C11), "0") -> 1.6825688 | J11: 100
A12: BC10 | B12: BEATRICE | C12: 46211.999 | D12: Done | E12: =IF(D12<>"",IF(E12="",NOW(),E12),"") -> 46210.317 | F12: =if(D12 = "", 0,IF(E12<C12,0.5,0)) -> 0.5 | H12: =if(D12 <> "", ABS(E12-C12), "0") -> 1.6825393
A13: BC11 | B13: ROSHIEL | C13: 46213.999 | D13: done | E13: =IF(D13<>"",IF(E13="",NOW(),E13),"") -> 46217.466 | F13: =if(D13 = "", 0,IF(E13<C13,0.5,0)) -> 0 | H13: =if(D13 <> "", ABS(E13-C13), "0") -> 3.4667156
A14: BC13 | B14: GELO | C14: 46213.999 | D14: done | E14: =IF(D14<>"",IF(E14="",NOW(),E14),"") -> 46212.581 | F14: =if(D14 = "", 0,IF(E14<C14,0.5,0)) -> 0.5 | H14: =if(D14 <> "", ABS(E14-C14), "0") -> 1.41836
A15: BC14 | B15: BRYLLE | C15: 46213.999 | D15: done | E15: =IF(D15<>"",IF(E15="",NOW(),E15),"") -> 46213.067 | F15: =if(D15 = "", 0,IF(E15<C15,0.5,0)) -> 0.5 | H15: =if(D15 <> "", ABS(E15-C15), "0") -> 0.9319416
A16: BC15 | B16: BRYLLE | C16: 46218.999 | D16: done | E16: =IF(D16<>"",IF(E16="",NOW(),E16),"") -> 46217.54 | F16: =if(D16 = "", 0,IF(E16<C16,0.5,0)) -> 0.5 | H16: =if(D16 <> "", ABS(E16-C16), "0") -> 1.4589966
A17: BC17 | B17: GELO | C17: 46218.999 | D17: done | E17: =IF(D17<>"",IF(E17="",NOW(),E17),"") -> 46217.502 | F17: =if(D17 = "", 0,IF(E17<C17,0.5,0)) -> 0.5 | H17: =if(D17 <> "", ABS(E17-C17), "0") -> 1.4974535
A18: BC19 | B18: BEATRICE | C18: 46220.999 | D18: Done | E18: =IF(D18<>"",IF(E18="",NOW(),E18),"") -> 46220.144 | F18: =if(D18 = "", 0,IF(E18<C18,0.5,0)) -> 0.5 | H18: =if(D18 <> "", ABS(E18-C18), "0") -> 0.855616
A19: BC20 | B19: SARAH | C19: 46220.999 | D19: Done | E19: =IF(D19<>"",IF(E19="",NOW(),E19),"") -> 46220.156 | F19: =if(D19 = "", 0,IF(E19<C19,0.5,0)) -> 0.5 | H19: =if(D19 <> "", ABS(E19-C19), "0") -> 0.84313039
A20: BC21 | B20: GELO | C20: 46224.999 | D20: done | E20: =IF(D20<>"",IF(E20="",NOW(),E20),"") -> 46227.526 | F20: =if(D20 = "", 0,IF(E20<C20,0.5,0)) -> 0 | H20: =if(D20 <> "", ABS(E20-C20), "0") -> 2.5270661
A21: BC23 | B21: ARVIN | C21: 46224.999 | D21: Done | E21: =IF(D21<>"",IF(E21="",NOW(),E21),"") -> 46223.563 | F21: =if(D21 = "", 0,IF(E21<C21,0.5,0)) -> 0.5 | H21: =if(D21 <> "", ABS(E21-C21), "0") -> 1.4366088
A22: BC24 | B22: SARAH | C22: 46226.999 | D22: Done | E22: =IF(D22<>"",IF(E22="",NOW(),E22),"") -> 46226.258 | F22: =if(D22 = "", 0,IF(E22<C22,0.5,0)) -> 0.5 | H22: =if(D22 <> "", ABS(E22-C22), "0") -> 0.74168804
A23: BC25 | B23: ARVIN | C23: 46226.999 | D23: Done | E23: =IF(D23<>"",IF(E23="",NOW(),E23),"") -> 46225.577 | F23: =if(D23 = "", 0,IF(E23<C23,0.5,0)) -> 0.5 | H23: =if(D23 <> "", ABS(E23-C23), "0") -> 1.4227937 | J23: 100
A24: BC27 | B24: ROSHIEL | C24: 46227.999 | D24: done | E24: =IF(D24<>"",IF(E24="",NOW(),E24),"") -> 46232.111 | F24: =if(D24 = "", 0,IF(E24<C24,0.5,0)) -> 0 | H24: =if(D24 <> "", ABS(E24-C24), "0") -> 4.1113452 | J24: 100
A25: BC28 | B25: SARAH | C25: 46227.999 | D25: done | E25: =IF(D25<>"",IF(E25="",NOW(),E25),"") -> 46227.354 | F25: =if(D25 = "", 0,IF(E25<C25,0.5,0)) -> 0.5 | H25: =if(D25 <> "", ABS(E25-C25), "0") -> 0.6456514 | J25: 0
A26: AB
A27: BP | B27: Assigned to | C27: Due | D27: Status | E27: Date Completed | F27: Score | H27: days Difference
A28: AB00 | B28: BRYLLE | C28: 46233.999 | D28: done | E28: =IF(D28<>"",IF(E28="",NOW(),E28),"") -> 46232.329 | F28: =if(D28 = "", 0,IF(E28<C28,0.5,0)) -> 0.5 | H28: =if(D28 <> "", ABS(E28-C28), "0") -> 1.6704617
A29: AB01 | B29: BRYLLE | C29: 46233.999 | D29: done | E29: =IF(D29<>"",IF(E29="",NOW(),E29),"") -> 46232.329 | F29: =if(D29 = "", 0,IF(E29<C29,0.5,0)) -> 0.5 | H29: =if(D29 <> "", ABS(E29-C29), "0") -> 1.6704204
A30: AB04 | B30: ROSHIEL | C30: 46205.999 | D30: done | E30: =IF(D30<>"",IF(E30="",NOW(),E30),"") -> 46204.232 | F30: =if(D30 = "", 0,IF(E30<C30,0.5,0)) -> 0.5 | H30: =if(D30 <> "", ABS(E30-C30), "0") -> 1.7673523
A31: AB07 | B31: BEATRICE | C31: 46206.999 | D31: Done | E31: =IF(D31<>"",IF(E31="",NOW(),E31),"") -> 46208.945 | F31: =if(D31 = "", 0,IF(E31<C31,0.5,0)) -> 0 | H31: =if(D31 <> "", ABS(E31-C31), "0") -> 1.9452401
A32: AB10 | B32: ROSHIEL | C32: 46211.999 | D32: done | E32: =IF(D32<>"",IF(E32="",NOW(),E32),"") -> 46210.5 | F32: =if(D32 = "", 0,IF(E32<C32,0.5,0)) -> 0.5 | H32: =if(D32 <> "", ABS(E32-C32), "0") -> 1.4988499
A33: AB13 | B33: BRYLLE | C33: 46213.999 | D33: done | E33: =IF(D33<>"",IF(E33="",NOW(),E33),"") -> 46213.067 | F33: =if(D33 = "", 0,IF(E33<C33,0.5,0)) -> 0.5 | H33: =if(D33 <> "", ABS(E33-C33), "0") -> 0.9320814
A34: AB16 | B34: BEATRICE | C34: 46218.999 | D34: Done | E34: =IF(D34<>"",IF(E34="",NOW(),E34),"") -> 46218.033 | F34: =if(D34 = "", 0,IF(E34<C34,0.5,0)) -> 0.5 | H34: =if(D34 <> "", ABS(E34-C34), "0") -> 0.96614804
A35: AB19 | B35: BRYLLE | C35: 46220.999 | D35: done | E35: =IF(D35<>"",IF(E35="",NOW(),E35),"") -> 46231.1 | F35: =if(D35 = "", 0,IF(E35<C35,0.5,0)) -> 0 | H35: =if(D35 <> "", ABS(E35-C35), "0") -> 10.100663
A36: AB22 | B36: ART | C36: 46224.999 | D36: done | E36: =IF(D36<>"",IF(E36="",NOW(),E36),"") -> 46225.383 | F36: =if(D36 = "", 0,IF(E36<C36,0.5,0)) -> 0 | H36: =if(D36 <> "", ABS(E36-C36), "0") -> 0.3841566
A37: AB25 | B37: ART | C37: 46226.999 | D37: done | E37: =IF(D37<>"",IF(E37="",NOW(),E37),"") -> 46230.041 | F37: =if(D37 = "", 0,IF(E37<C37,0.5,0)) -> 0 | H37: =if(D37 <> "", ABS(E37-C37), "0") -> 3.0416014
A38: AB26 | B38: ART | C38: 46227.999 | D38: done | E38: =IF(D38<>"",IF(E38="",NOW(),E38),"") -> 46230.041 | F38: =if(D38 = "", 0,IF(E38<C38,0.5,0)) -> 0 | H38: =if(D38 <> "", ABS(E38-C38), "0") -> 2.041632
A39: AB28 | B39: SARAH | C39: 46227.999 | E39: =IF(D39<>"",IF(E39="",NOW(),E39),"") | F39: =if(D39 = "", 0,IF(E39<C39,0.5,0)) -> 0 | H39: =if(D39 <> "", ABS(E39-C39), "0") -> 0

Sheet AUG
A1: SOI BP's Completed TRACKER
A2: AUGUST 2026
A3: BC
A4: BP | B4: Assigned to | C4: Due | D4: Status | E4: Date Completed | F4: Score | H4: days Difference
A5: BC00 | B5: BEATRICE | C5: 46262.999 | D5: Done | E5: =IF(D5<>"",IF(E5="",NOW(),E5),"") -> 46261.112 | F5: =if(D5 = "", 0,IF(E5<C5,0.5,0)) -> 0.5 | H5: =if(D5 <> "", ABS(E5-C5), "0") -> 1.8877174
A6: BC01 | B6: BEATRICE | C6: 46262.999 | D6: Done | E6: =IF(D6<>"",IF(E6="",NOW(),E6),"") -> 46261.112 | F6: =if(D6 = "", 0,IF(E6<C6,0.5,0)) -> 0.5 | H6: =if(D6 <> "", ABS(E6-C6), "0") -> 1.887666
A7: BC03 | B7: ARVIN | C7: 46234.999 | D7: Done | E7: =IF(D7<>"",IF(E7="",NOW(),E7),"") -> 46233.562 | F7: =if(D7 = "", 0,IF(E7<C7,0.5,0)) -> 0.5 | H7: =IF(D7 <> "", ABS(E7-C7), "0") -> 1.4368739
A8: BC04 | B8: BRYLLE | C8: 46234.999 | D8: done | E8: =IF(D8<>"",IF(E8="",NOW(),E8),"") -> 46234.22 | F8: =if(D8 = "", 0,IF(E8<C8,0.5,0)) -> 0.5 | H8: =if(D8 <> "", ABS(E8-C8), "0") -> 0.77934449
A9: BC05 | B9: ROSHIEL | C9: 46239.999 | D9: done | E9: =IF(D9<>"",IF(E9="",NOW(),E9),"") -> 46239.288 | F9: =if(D9 = "", 0,IF(E9<C9,0.5,0)) -> 0.5 | H9: =if(D9 <> "", ABS(E9-C9), "0") -> 0.71126759
A10: BC07 | B10: ROSHIEL | C10: 46239.999 | D10: done | E10: =IF(D10<>"",IF(E10="",NOW(),E10),"") -> 46239.288 | F10: =if(D10 = "", 0,IF(E10<C10,0.5,0)) -> 0.5 | H10: =if(D10 <> "", ABS(E10-C10), "0") -> 0.71123903
A11: BC09 | B11: BEATRICE | C11: 46241.999 | D11: Done | E11: =IF(D11<>"",IF(E11="",NOW(),E11),"") -> 46240.019 | F11: =if(D11 = "", 0,IF(E11<C11,0.5,0)) -> 0.5 | H11: =if(D11 <> "", ABS(E11-C11), "0") -> 1.9798692
A12: BC10 | B12: BEATRICE | C12: 46241.999 | D12: Done | E12: =IF(D12<>"",IF(E12="",NOW(),E12),"") -> 46240.019 | F12: =if(D12 = "", 0,IF(E12<C12,0.5,0)) -> 0.5 | H12: =if(D12 <> "", ABS(E12-C12), "0") -> 1.9798219
A13: BC11 | B13: ROSHIEL | C13: 46244.999 | D13: Done | E13: =IF(D13<>"",IF(E13="",NOW(),E13),"") -> 46267.311 | F13: =if(D13 = "", 0,IF(E13<C13,0.5,0)) -> 0 | H13: =if(D13 <> "", ABS(E13-C13), "0") -> 22.311597
A14: BC13 | B14: GELO | C14: 46246.999 | D14: done | E14: =IF(D14<>"",IF(E14="",NOW(),E14),"") -> 46244.403 | F14: =if(D14 = "", 0,IF(E14<C14,0.5,0)) -> 0.5 | H14: =if(D14 <> "", ABS(E14-C14), "0") -> 2.5965789
A15: BC14 | B15: BRYLLE | C15: 46246.999 | D15: done | E15: =IF(D15<>"",IF(E15="",NOW(),E15),"") -> 46245.474 | F15: =if(D15 = "", 0,IF(E15<C15,0.5,0)) -> 0.5 | H15: =if(D15 <> "", ABS(E15-C15), "0") -> 1.5251097
A16: BC15 | B16: BRYLLE | C16: 46248.999 | D16: done | E16: =IF(D16<>"",IF(E16="",NOW(),E16),"") -> 46245.475 | F16: =if(D16 = "", 0,IF(E16<C16,0.5,0)) -> 0.5 | H16: =if(D16 <> "", ABS(E16-C16), "0") -> 3.5246348
A17: BC17 | B17: GELO | C17: 46248.999 | D17: done | E17: =IF(D17<>"",IF(E17="",NOW(),E17),"") -> 46244.403 | F17: =if(D17 = "", 0,IF(E17<C17,0.5,0)) -> 0.5 | H17: =if(D17 <> "", ABS(E17-C17), "0") -> 4.5964951
A18: BC19 | B18: BEATRICE | C18: 46252.999 | D18: Done | E18: =IF(D18<>"",IF(E18="",NOW(),E18),"") -> 46251.115 | F18: =if(D18 = "", 0,IF(E18<C18,0.5,0)) -> 0.5 | H18: =if(D18 <> "", ABS(E18-C18), "0") -> 1.8841344 | J18: 100
A19: BC20 | B19: ARVIN | C19: 46252.999 | D19: Done | E19: =IF(D19<>"",IF(E19="",NOW(),E19),"") -> 46251.576 | F19: =if(D19 = "", 0,IF(E19<C19,0.5,0)) -> 0.5 | H19: =if(D19 <> "", ABS(E19-C19), "0") -> 1.423131 | J19: 0
A20: BC21 | B20: GELO | C20: 46255.999 | D20: done | E20: =IF(D20<>"",IF(E20="",NOW(),E20),"") -> 46254.463 | F20: =if(D20 = "", 0,IF(E20<C20,0.5,0)) -> 0.5 | H20: =if(D20 <> "", ABS(E20-C20), "0") -> 1.5363992
A21: BC23 | B21: ARVIN | C21: 46255.999 | D21: Done | E21: =IF(D21<>"",IF(E21="",NOW(),E21),"") -> 46254.585 | F21: =if(D21 = "", 0,IF(E21<C21,0.5,0)) -> 0.5 | H21: =if(D21 <> "", ABS(E21-C21), "0") -> 1.4141786
A22: BC24 | B22: WILL | C22: 46255.999 | D22: Done | E22: =IF(D22<>"",IF(E22="",NOW(),E22),"") -> 46267.311 | F22: =if(D22 = "", 0,IF(E22<C22,0.5,0)) -> 0 | H22: =if(D22 <> "", ABS(E22-C22), "0") -> 11.311676
A23: BC25 | B23: ARVIN | C23: 46255.999 | D23: Done | E23: =IF(D23<>"",IF(E23="",NOW(),E23),"") -> 46254.585 | F23: =if(D23 = "", 0,IF(E23<C23,0.5,0)) -> 0.5 | H23: =if(D23 <> "", ABS(E23-C23), "0") -> 1.4141294
A24: BC27 | B24: WILL | C24: 46260.999 | D24: Done | E24: =IF(D24<>"",IF(E24="",NOW(),E24),"") -> 46267.311 | F24: =if(D24 = "", 0,IF(E24<C24,0.5,0)) -> 0 | H24: =if(D24 <> "", ABS(E24-C24), "0") -> 6.3117053
A25: BC28 | B25: ARVIN | C25: 46260.999 | D25: Done | E25: =IF(D25<>"",IF(E25="",NOW(),E25),"") -> 46259.507 | F25: =if(D25 = "", 0,IF(E25<C25,0.5,0)) -> 0.5 | H25: =if(D25 <> "", ABS(E25-C25), "0") -> 1.4922996
A26: AB
A27: BP | B27: Assigned to | C27: Due | D27: Status | E27: Date Completed | F27: Score | H27: days Difference
A28: AB00 | B28: BRYLLE | C28: 46262.999 | D28: done | E28: =IF(D28<>"",IF(E28="",NOW(),E28),"") -> 46261.112 | F28: =if(D28 = "", 0,IF(E28<C28,0.5,0)) -> 0.5 | H28: =if(D28 <> "", ABS(E28-C28), "0") -> 1.8874317
A29: AB01 | B29: BRYLLE | C29: 46262.999 | D29: done | E29: =IF(D29<>"",IF(E29="",NOW(),E29),"") -> 46261.112 | F29: =if(D29 = "", 0,IF(E29<C29,0.5,0)) -> 0.5 | H29: =if(D29 <> "", ABS(E29-C29), "0") -> 1.8873944
A30: AB04 | B30: BEATRICE | C30: 46234.999 | D30: done | E30: =IF(D30<>"",IF(E30="",NOW(),E30),"") -> 46234.445 | F30: =if(D30 = "", 0,IF(E30<C30,0.5,0)) -> 0.5 | H30: =IF(D30 <> "", ABS(E30-C30), "0") -> 0.55461091
A31: AB07 | B31: BEATRICE | C31: 46239.999 | D31: Done | E31: =IF(D31<>"",IF(E31="",NOW(),E31),"") -> 46238.018 | F31: =if(D31 = "", 0,IF(E31<C31,0.5,0)) -> 0.5 | H31: =if(D31 <> "", ABS(E31-C31), "0") -> 1.9808629
A32: AB10 | B32: ROSHIEL | C32: 46241.999 | E32: =IF(D32<>"",IF(E32="",NOW(),E32),"") | F32: =if(D32 = "", 0,IF(E32<C32,0.5,0)) -> 0 | H32: =if(D32 <> "", ABS(E32-C32), "0") -> 0
A33: AB13 | B33: BRYLLE | C33: 46246.999 | D33: done | E33: =IF(D33<>"",IF(E33="",NOW(),E33),"") -> 46245.474 | F33: =if(D33 = "", 0,IF(E33<C33,0.5,0)) -> 0.5 | H33: =if(D33 <> "", ABS(E33-C33), "0") -> 1.5250503
A34: AB16 | B34: BEATRICE | C34: 46248.999 | D34: Done | E34: =IF(D34<>"",IF(E34="",NOW(),E34),"") -> 46247.116 | F34: =if(D34 = "", 0,IF(E34<C34,0.5,0)) -> 0.5 | H34: =if(D34 <> "", ABS(E34-C34), "0") -> 1.8832519
A35: AB19 | B35: BRYLLE | C35: 46252.999 | D35: done | E35: =IF(D35<>"",IF(E35="",NOW(),E35),"") -> 46252.047 | F35: =if(D35 = "", 0,IF(E35<C35,0.5,0)) -> 0.5 | H35: =if(D35 <> "", ABS(E35-C35), "0") -> 0.95232325
A36: AB22 | B36: ART | C36: 46255.999 | D36: done | E36: =IF(D36<>"",IF(E36="",NOW(),E36),"") -> 46255.248 | F36: =if(D36 = "", 0,IF(E36<C36,0.5,0)) -> 0.5 | H36: =if(D36 <> "", ABS(E36-C36), "0") -> 0.75103566
A37: AB25 | B37: ART | C37: 46255.999 | D37: dne | E37: =IF(D37<>"",IF(E37="",NOW(),E37),"") -> 46255.248 | F37: =if(D37 = "", 0,IF(E37<C37,0.5,0)) -> 0.5 | H37: =if(D37 <> "", ABS(E37-C37), "0") -> 0.75102586
A38: AB26 | B38: ART | C38: 46260.999 | D38: done | E38: =IF(D38<>"",IF(E38="",NOW(),E38),"") -> 46260.291 | F38: =if(D38 = "", 0,IF(E38<C38,0.5,0)) -> 0.5 | H38: =if(D38 <> "", ABS(E38-C38), "0") -> 0.70812811
A39: AB28 | B39: DIANA | C39: 46260.999 | D39: done | E39: =IF(D39<>"",IF(E39="",NOW(),E39),"") -> 46267.343 | F39: =if(D39 = "", 0,IF(E39<C39,0.5,0)) -> 0 | H39: =if(D39 <> "", ABS(E39-C39), "0") -> 6.3441795

Sheet SEP
A1: SOI BP's Completed TRACKER
A2: SEPTEMBER 2026
A3: BC
A4: BP | B4: Assigned to | C4: Due | D4: Status | E4: Date Completed | F4: Score | H4: days Difference
A5: BC00 | B5: BEATRICE | C5: 46294.999 | E5: =IF(D5<>"",IF(E5="",NOW(),E5),"") | F5: =if(D5 = "", 0,IF(E5<C5,0.5,0)) -> 0 | H5: =if(D5 <> "", ABS(E5-C5), "0") -> 0
A6: BC01 | B6: BEATRICE | C6: 46294.999 | E6: =IF(D6<>"",IF(E6="",NOW(),E6),"") | F6: =if(D6 = "", 0,IF(E6<C6,0.5,0)) -> 0 | H6: =if(D6 <> "", ABS(E6-C6), "0") -> 0
A7: BC03 | B7: ARVIN | C7: 46267.999 | D7: Done | E7: =IF(D7<>"",IF(E7="",NOW(),E7),"") -> 46266.381 | F7: =if(D7 = "", 0,IF(E7<C7,0.5,0)) -> 0.5 | H7: =if(D7 <> "", ABS(E7-C7), "0") -> 1.6182923
A8: BC04 | B8: BRYLLE | C8: 46267.999 | D8: done | E8: =IF(D8<>"",IF(E8="",NOW(),E8),"") -> 46266.44 | F8: =if(D8 = "", 0,IF(E8<C8,0.5,0)) -> 0.5 | H8: =if(D8 <> "", ABS(E8-C8), "0") -> 1.5588109
A9: BC05 | B9: DIANA | C9: 46269.999 | E9: =IF(D9<>"",IF(E9="",NOW(),E9),"") | F9: =if(D9 = "", 0,IF(E9<C9,0.5,0)) -> 0 | H9: =if(D9 <> "", ABS(E9-C9), "0") -> 0
A10: BC07 | B10: DIANA | C10: 46269.999 | E10: =IF(D10<>"",IF(E10="",NOW(),E10),"") | F10: =if(D10 = "", 0,IF(E10<C10,0.5,0)) -> 0 | H10: =if(D10 <> "", ABS(E10-C10), "0") -> 0
A11: BC09 | B11: BEATRICE | C11: 46273.999 | D11: DONE | E11: =IF(D11<>"",IF(E11="",NOW(),E11),"") -> 46272.257 | F11: =if(D11 = "", 0,IF(E11<C11,0.5,0)) -> 0.5 | H11: =if(D11 <> "", ABS(E11-C11), "0") -> 1.7423856
A12: BC10 | B12: BEATRICE | C12: 46273.999 | D12: DONE | E12: =IF(D12<>"",IF(E12="",NOW(),E12),"") -> 46272.257 | F12: =if(D12 = "", 0,IF(E12<C12,0.5,0)) -> 0.5 | H12: =if(D12 <> "", ABS(E12-C12), "0") -> 1.7422689
A13: BC11 | B13: WILL | C13: 46275.999 | E13: =IF(D13<>"",IF(E13="",NOW(),E13),"") | F13: =if(D13 = "", 0,IF(E13<C13,0.5,0)) -> 0 | H13: =if(D13 <> "", ABS(E13-C13), "0") -> 0
A14: BC13 | B14: GELO | C14: 46276.999 | D14: done | E14: =IF(D14<>"",IF(E14="",NOW(),E14),"") -> 46275.08 | F14: =if(D14 = "", 0,IF(E14<C14,0.5,0)) -> 0.5 | H14: =if(D14 <> "", ABS(E14-C14), "0") -> 1.9188027
A15: BC14 | B15: BRYLLE | C15: 46276.999 | D15: done | E15: =IF(D15<>"",IF(E15="",NOW(),E15),"") -> 46276.012 | F15: =if(D15 = "", 0,IF(E15<C15,0.5,0)) -> 0.5 | H15: =if(D15 <> "", ABS(E15-C15), "0") -> 0.98753975
A16: BC15 | B16: BRYLLE | C16: 46280.999 | D16: done | E16: =IF(D16<>"",IF(E16="",NOW(),E16),"") -> 46280.307 | F16: =if(D16 = "", 0,IF(E16<C16,0.5,0)) -> 0.5 | H16: =if(D16 <> "", ABS(E16-C16), "0") -> 0.69259682
A17: BC17 | B17: GELO | C17: 46280.999 | D17: done | E17: =IF(D17<>"",IF(E17="",NOW(),E17),"") -> 46279.344 | F17: =if(D17 = "", 0,IF(E17<C17,0.5,0)) -> 0.5 | H17: =if(D17 <> "", ABS(E17-C17), "0") -> 1.6553533
A18: BC19 | B18: BEATRICE | C18: 46283.999 | E18: =IF(D18<>"",IF(E18="",NOW(),E18),"") | F18: =if(D18 = "", 0,IF(E18<C18,0.5,0)) -> 0 | H18: =if(D18 <> "", ABS(E18-C18), "0") -> 0
A19: BC20 | B19: ARVIN | C19: 46283.999 | E19: =IF(D19<>"",IF(E19="",NOW(),E19),"") | F19: =if(D19 = "", 0,IF(E19<C19,0.5,0)) -> 0 | H19: =if(D19 <> "", ABS(E19-C19), "0") -> 0
A20: BC21 | B20: GELO | C20: 46286.999 | E20: =IF(D20<>"",IF(E20="",NOW(),E20),"") | F20: =if(D20 = "", 0,IF(E20<C20,0.5,0)) -> 0 | H20: =if(D20 <> "", ABS(E20-C20), "0") -> 0
A21: BC23 | B21: ARVIN | C21: 46286.999 | E21: =IF(D21<>"",IF(E21="",NOW(),E21),"") | F21: =if(D21 = "", 0,IF(E21<C21,0.5,0)) -> 0 | H21: =if(D21 <> "", ABS(E21-C21), "0") -> 0
A22: BC24 | B22: WILL | C22: 46288.999 | E22: =IF(D22<>"",IF(E22="",NOW(),E22),"") | F22: =if(D22 = "", 0,IF(E22<C22,0.5,0)) -> 0 | H22: =if(D22 <> "", ABS(E22-C22), "0") -> 0
A23: BC25 | B23: ARVIN | C23: 46288.999 | E23: =IF(D23<>"",IF(E23="",NOW(),E23),"") | F23: =if(D23 = "", 0,IF(E23<C23,0.5,0)) -> 0 | H23: =if(D23 <> "", ABS(E23-C23), "0") -> 0
A24: BC27 | B24: WILL | C24: 46290.999 | E24: =IF(D24<>"",IF(E24="",NOW(),E24),"") | F24: =if(D24 = "", 0,IF(E24<C24,0.5,0)) -> 0 | H24: =if(D24 <> "", ABS(E24-C24), "0") -> 0
A25: BC28 | B25: ARVIN | C25: 46290.999 | E25: =IF(D25<>"",IF(E25="",NOW(),E25),"") | F25: =if(D25 = "", 0,IF(E25<C25,0.5,0)) -> 0 | H25: =if(D25 <> "", ABS(E25-C25), "0") -> 0
A26: AB
A27: BP | B27: Assigned to | C27: Due | D27: Status | E27: Date Completed | F27: Score | H27: days Difference
A28: AB00 | B28: BRYLLE | C28: 46294.999 | E28: =IF(D28<>"",IF(E28="",NOW(),E28),"") | F28: =if(D28 = "", 0,IF(E28<C28,0.5,0)) -> 0 | H28: =if(D28 <> "", ABS(E28-C28), "0") -> 0
A29: AB01 | B29: BRYLLE | C29: 46294.999 | E29: =IF(D29<>"",IF(E29="",NOW(),E29),"") | F29: =if(D29 = "", 0,IF(E29<C29,0.5,0)) -> 0 | H29: =if(D29 <> "", ABS(E29-C29), "0") -> 0
A30: AB04 | B30: BEATRICE | C30: 46267.999 | D30: DONE | E30: =IF(D30<>"",IF(E30="",NOW(),E30),"") -> 46266.256 | F30: =if(D30 = "", 0,IF(E30<C30,0.5,0)) -> 0.5 | H30: =if(D30 <> "", ABS(E30-C30), "0") -> 1.7432473
A31: AB07 | B31: BEATRICE | C31: 46269.999 | D31: DONE | E31: =IF(D31<>"",IF(E31="",NOW(),E31),"") -> 46269.093 | F31: =if(D31 = "", 0,IF(E31<C31,0.5,0)) -> 0.5 | H31: =if(D31 <> "", ABS(E31-C31), "0") -> 0.90607281
A32: AB10 | B32: ARVIN | C32: 46273.999 | D32: Done | E32: =IF(D32<>"",IF(E32="",NOW(),E32),"") -> 46272.443 | F32: =if(D32 = "", 0,IF(E32<C32,0.5,0)) -> 0.5 | H32: =if(D32 <> "", ABS(E32-C32), "0") -> 1.5562623
A33: AB13 | B33: BRYLLE | C33: 46276.999 | D33: done | E33: =IF(D33<>"",IF(E33="",NOW(),E33),"") -> 46276.012 | F33: =if(D33 = "", 0,IF(E33<C33,0.5,0)) -> 0.5 | H33: =if(D33 <> "", ABS(E33-C33), "0") -> 0.98768734
A34: AB16 | B34: BEATRICE | C34: 46280.999 | D34: Done | E34: =IF(D34<>"",IF(E34="",NOW(),E34),"") -> 46279.101 | F34: =if(D34 = "", 0,IF(E34<C34,0.5,0)) -> 0.5 | H34: =if(D34 <> "", ABS(E34-C34), "0") -> 1.8987752
A35: AB19 | B35: BRYLLE | C35: 46283.999 | E35: =IF(D35<>"",IF(E35="",NOW(),E35),"") | F35: =if(D35 = "", 0,IF(E35<C35,0.5,0)) -> 0 | H35: =if(D35 <> "", ABS(E35-C35), "0") -> 0
A36: AB22 | B36: ART | C36: 46286.999 | E36: =IF(D36<>"",IF(E36="",NOW(),E36),"") | F36: =if(D36 = "", 0,IF(E36<C36,0.5,0)) -> 0 | H36: =if(D36 <> "", ABS(E36-C36), "0") -> 0
A37: AB25 | B37: ART | C37: 46288.999 | E37: =IF(D37<>"",IF(E37="",NOW(),E37),"") | F37: =if(D37 = "", 0,IF(E37<C37,0.5,0)) -> 0 | H37: =if(D37 <> "", ABS(E37-C37), "0") -> 0
A38: AB26 | B38: ART | C38: 46290.999 | E38: =IF(D38<>"",IF(E38="",NOW(),E38),"") | F38: =if(D38 = "", 0,IF(E38<C38,0.5,0)) -> 0 | H38: =if(D38 <> "", ABS(E38-C38), "0") -> 0
A39: AB28 | B39: DIANA | C39: 46290.999 | E39: =IF(D39<>"",IF(E39="",NOW(),E39),"") | F39: =if(D39 = "", 0,IF(E39<C39,0.5,0)) -> 0 | H39: =if(D39 <> "", ABS(E39-C39), "0") -> 0
K43: 0.5
...

Sheet OCT
A1: SOI BP's Completed TRACKER
A2: OCTOBER 2026
A3: BC
A4: BP | B4: Assigned to | C4: Due | D4: Status | E4: Date Completed | F4: Score | H4: days Difference
A5: BC00 | B5: BEATRICE | C5: 46325.999 | E5: =IF(D5<>"",IF(E5="",NOW(),E5),"") | F5: =if(D5 = "", 0,IF(E5<C5,0.5,0)) -> 0 | H5: =if(D5 <> "", ABS(E5-C5), "0") -> 0
A6: BC01 | B6: BEATRICE | C6: 46325.999 | E6: =IF(D6<>"",IF(E6="",NOW(),E6),"") | F6: =if(D6 = "", 0,IF(E6<C6,0.5,0)) -> 0 | H6: =if(D6 <> "", ABS(E6-C6), "0") -> 0
A7: BC03 | B7: ARVIN | C7: 46297.999 | E7: =IF(D7<>"",IF(E7="",NOW(),E7),"") | F7: =if(D7 = "", 0,IF(E7<C7,0.5,0)) -> 0 | H7: =if(D7 <> "", ABS(E7-C7), "0") -> 0
